{
 "cells": [
  {
   "cell_type": "code",
   "execution_count": 1,
   "metadata": {},
   "outputs": [],
   "source": [
    "%load_ext autoreload\n",
    "%autoreload 2"
   ]
  },
  {
   "cell_type": "code",
   "execution_count": 2,
   "metadata": {},
   "outputs": [
    {
     "name": "stderr",
     "output_type": "stream",
     "text": [
      "/home/diego/Myopt/Miniconda/miniconda3/envs/UIBCDF_lab_dev/lib/python3.7/site-packages/yank/experiment.py:1161: YAMLLoadWarning: calling yaml.load() without Loader=... is deprecated, as the default Loader is unsafe. Please read https://msg.pyyaml.org/load for full details.\n",
      "  \"\"\")\n"
     ]
    }
   ],
   "source": [
    "import molmodmt as m3t"
   ]
  },
  {
   "cell_type": "code",
   "execution_count": 3,
   "metadata": {},
   "outputs": [],
   "source": [
    "system_EBNA1_DNA = m3t.load('pdb:1B3T')"
   ]
  },
  {
   "cell_type": "code",
   "execution_count": 5,
   "metadata": {},
   "outputs": [],
   "source": [
    "system_EBNA1_DNA = m3t.remove_solvent(system_EBNA1_DNA)"
   ]
  },
  {
   "cell_type": "code",
   "execution_count": 6,
   "metadata": {},
   "outputs": [],
   "source": [
    "sequence_system = m3t.convert(system_EBNA1_DNA, 'aminoacids1')"
   ]
  },
  {
   "cell_type": "code",
   "execution_count": 15,
   "metadata": {},
   "outputs": [
    {
     "data": {
      "text/plain": [
       "'XXXXXXXXXXXXXXXXXXXXXXXXKGGWFGKHRGQGGSNPKFENIAEGLRALLARSHVERTTDEGTWVAGVFVYGGSKTSLYNLRRGTALAIPQCRLTPLSRLPFGMAPGPGPQPGPLRESIVCYFMVFLQTHIFAEVLKDAIKDLVMTKPAPTCNIRVTVCSFDDGVDLPKGGWFGKHRGQGGSNPKFENIAEGLRALLARSHVERTTDEGTWVAGVFVYGGSKTSLYNLRRGTALAIPQCRLTPLSRLPFGMAPGPGPQPGPLRESIVCYFMVFLQTHIFAEVLKDAIKDLVMTKPAPTCNIRVTVCSFDDGVDLP'"
      ]
     },
     "execution_count": 15,
     "metadata": {},
     "output_type": "execute_result"
    }
   ],
   "source": [
    "sequence_system"
   ]
  },
  {
   "cell_type": "code",
   "execution_count": 9,
   "metadata": {},
   "outputs": [],
   "source": [
    "target_sequence = sequence_system.replace('KGGWFGK','QGDGGRRK'+'KGGWFGK')"
   ]
  },
  {
   "cell_type": "code",
   "execution_count": 23,
   "metadata": {},
   "outputs": [
    {
     "data": {
      "text/plain": [
       "'XXXXXXXXXXXXXXXXXXXXXXXXQGDGGRRKKGGWFGKHRGQGGSNPKFENIAEGLRALLARSHVERTTDEGTWVAGVFVYGGSKTSLYNLRRGTALAIPQCRLTPLSRLPFGMAPGPGPQPGPLRESIVCYFMVFLQTHIFAEVLKDAIKDLVMTKPAPTCNIRVTVCSFDDGVDLPQGDGGRRKKGGWFGKHRGQGGSNPKFENIAEGLRALLARSHVERTTDEGTWVAGVFVYGGSKTSLYNLRRGTALAIPQCRLTPLSRLPFGMAPGPGPQPGPLRESIVCYFMVFLQTHIFAEVLKDAIKDLVMTKPAPTCNIRVTVCSFDDGVDLP'"
      ]
     },
     "execution_count": 23,
     "metadata": {},
     "output_type": "execute_result"
    }
   ],
   "source": [
    "target_sequence"
   ]
  },
  {
   "cell_type": "code",
   "execution_count": 25,
   "metadata": {},
   "outputs": [
    {
     "ename": "SystemError",
     "evalue": "<built-in function _make_score_matrix_fast> returned a result with an error set",
     "output_type": "error",
     "traceback": [
      "\u001b[0;31m---------------------------------------------------------------------------\u001b[0m",
      "\u001b[0;31mKeyError\u001b[0m                                  Traceback (most recent call last)",
      "\u001b[0;32m~/Myopt/Miniconda/miniconda3/envs/UIBCDF_lab_dev/lib/python3.7/site-packages/Bio/pairwise2.py\u001b[0m in \u001b[0;36m__call__\u001b[0;34m(self, charA, charB)\u001b[0m\n\u001b[1;32m   1030\u001b[0m             \u001b[0mcharB\u001b[0m\u001b[0;34m,\u001b[0m \u001b[0mcharA\u001b[0m \u001b[0;34m=\u001b[0m \u001b[0mcharA\u001b[0m\u001b[0;34m,\u001b[0m \u001b[0mcharB\u001b[0m\u001b[0;34m\u001b[0m\u001b[0;34m\u001b[0m\u001b[0m\n\u001b[0;32m-> 1031\u001b[0;31m         \u001b[0;32mreturn\u001b[0m \u001b[0mself\u001b[0m\u001b[0;34m.\u001b[0m\u001b[0mscore_dict\u001b[0m\u001b[0;34m[\u001b[0m\u001b[0;34m(\u001b[0m\u001b[0mcharA\u001b[0m\u001b[0;34m,\u001b[0m \u001b[0mcharB\u001b[0m\u001b[0;34m)\u001b[0m\u001b[0;34m]\u001b[0m\u001b[0;34m\u001b[0m\u001b[0;34m\u001b[0m\u001b[0m\n\u001b[0m\u001b[1;32m   1032\u001b[0m \u001b[0;34m\u001b[0m\u001b[0m\n",
      "\u001b[0;31mKeyError\u001b[0m: ('.', 'P')",
      "\nThe above exception was the direct cause of the following exception:\n",
      "\u001b[0;31mSystemError\u001b[0m                               Traceback (most recent call last)",
      "\u001b[0;31mSystemError\u001b[0m: PyEval_EvalFrameEx returned a result with an error set",
      "\nThe above exception was the direct cause of the following exception:\n",
      "\u001b[0;31mSystemError\u001b[0m                               Traceback (most recent call last)",
      "\u001b[0;31mSystemError\u001b[0m: PyEval_EvalFrameEx returned a result with an error set",
      "\nThe above exception was the direct cause of the following exception:\n",
      "\u001b[0;31mSystemError\u001b[0m                               Traceback (most recent call last)",
      "\u001b[0;31mSystemError\u001b[0m: PyEval_EvalFrameEx returned a result with an error set",
      "\nThe above exception was the direct cause of the following exception:\n",
      "\u001b[0;31mSystemError\u001b[0m                               Traceback (most recent call last)",
      "\u001b[0;31mSystemError\u001b[0m: PyEval_EvalFrameEx returned a result with an error set",
      "\nThe above exception was the direct cause of the following exception:\n",
      "\u001b[0;31mSystemError\u001b[0m                               Traceback (most recent call last)",
      "\u001b[0;31mSystemError\u001b[0m: PyEval_EvalFrameEx returned a result with an error set",
      "\nThe above exception was the direct cause of the following exception:\n",
      "\u001b[0;31mSystemError\u001b[0m                               Traceback (most recent call last)",
      "\u001b[0;31mSystemError\u001b[0m: PyEval_EvalFrameEx returned a result with an error set",
      "\nThe above exception was the direct cause of the following exception:\n",
      "\u001b[0;31mSystemError\u001b[0m                               Traceback (most recent call last)",
      "\u001b[0;31mSystemError\u001b[0m: PyEval_EvalFrameEx returned a result with an error set",
      "\nThe above exception was the direct cause of the following exception:\n",
      "\u001b[0;31mSystemError\u001b[0m                               Traceback (most recent call last)",
      "\u001b[0;31mSystemError\u001b[0m: PyEval_EvalFrameEx returned a result with an error set",
      "\nThe above exception was the direct cause of the following exception:\n",
      "\u001b[0;31mSystemError\u001b[0m                               Traceback (most recent call last)",
      "\u001b[0;31mSystemError\u001b[0m: PyEval_EvalFrameEx returned a result with an error set",
      "\nThe above exception was the direct cause of the following exception:\n",
      "\u001b[0;31mSystemError\u001b[0m                               Traceback (most recent call last)",
      "\u001b[0;31mSystemError\u001b[0m: PyEval_EvalFrameEx returned a result with an error set",
      "\nThe above exception was the direct cause of the following exception:\n",
      "\u001b[0;31mSystemError\u001b[0m                               Traceback (most recent call last)",
      "\u001b[0;31mSystemError\u001b[0m: PyEval_EvalFrameEx returned a result with an error set",
      "\nThe above exception was the direct cause of the following exception:\n",
      "\u001b[0;31mSystemError\u001b[0m                               Traceback (most recent call last)",
      "\u001b[0;31mSystemError\u001b[0m: PyEval_EvalFrameEx returned a result with an error set",
      "\nThe above exception was the direct cause of the following exception:\n",
      "\u001b[0;31mSystemError\u001b[0m                               Traceback (most recent call last)",
      "\u001b[0;31mSystemError\u001b[0m: PyEval_EvalFrameEx returned a result with an error set",
      "\nThe above exception was the direct cause of the following exception:\n",
      "\u001b[0;31mSystemError\u001b[0m                               Traceback (most recent call last)",
      "\u001b[0;31mSystemError\u001b[0m: PyEval_EvalFrameEx returned a result with an error set",
      "\nThe above exception was the direct cause of the following exception:\n",
      "\u001b[0;31mSystemError\u001b[0m                               Traceback (most recent call last)",
      "\u001b[0;31mSystemError\u001b[0m: PyEval_EvalFrameEx returned a result with an error set",
      "\nThe above exception was the direct cause of the following exception:\n",
      "\u001b[0;31mSystemError\u001b[0m                               Traceback (most recent call last)",
      "\u001b[0;31mSystemError\u001b[0m: PyEval_EvalFrameEx returned a result with an error set",
      "\nThe above exception was the direct cause of the following exception:\n",
      "\u001b[0;31mSystemError\u001b[0m                               Traceback (most recent call last)",
      "\u001b[0;31mSystemError\u001b[0m: PyEval_EvalFrameEx returned a result with an error set",
      "\nThe above exception was the direct cause of the following exception:\n",
      "\u001b[0;31mSystemError\u001b[0m                               Traceback (most recent call last)",
      "\u001b[0;31mSystemError\u001b[0m: PyEval_EvalFrameEx returned a result with an error set",
      "\nThe above exception was the direct cause of the following exception:\n",
      "\u001b[0;31mSystemError\u001b[0m                               Traceback (most recent call last)",
      "\u001b[0;31mSystemError\u001b[0m: PyEval_EvalFrameEx returned a result with an error set",
      "\nThe above exception was the direct cause of the following exception:\n",
      "\u001b[0;31mSystemError\u001b[0m                               Traceback (most recent call last)",
      "\u001b[0;31mSystemError\u001b[0m: PyEval_EvalFrameEx returned a result with an error set",
      "\nThe above exception was the direct cause of the following exception:\n",
      "\u001b[0;31mSystemError\u001b[0m                               Traceback (most recent call last)",
      "\u001b[0;31mSystemError\u001b[0m: PyEval_EvalFrameEx returned a result with an error set",
      "\nThe above exception was the direct cause of the following exception:\n",
      "\u001b[0;31mSystemError\u001b[0m                               Traceback (most recent call last)",
      "\u001b[0;31mSystemError\u001b[0m: PyEval_EvalFrameEx returned a result with an error set",
      "\nThe above exception was the direct cause of the following exception:\n",
      "\u001b[0;31mSystemError\u001b[0m                               Traceback (most recent call last)",
      "\u001b[0;31mSystemError\u001b[0m: PyEval_EvalFrameEx returned a result with an error set",
      "\nThe above exception was the direct cause of the following exception:\n",
      "\u001b[0;31mSystemError\u001b[0m                               Traceback (most recent call last)",
      "\u001b[0;31mSystemError\u001b[0m: PyEval_EvalFrameEx returned a result with an error set",
      "\nThe above exception was the direct cause of the following exception:\n",
      "\u001b[0;31mSystemError\u001b[0m                               Traceback (most recent call last)",
      "\u001b[0;31mSystemError\u001b[0m: PyEval_EvalFrameEx returned a result with an error set",
      "\nThe above exception was the direct cause of the following exception:\n",
      "\u001b[0;31mSystemError\u001b[0m                               Traceback (most recent call last)",
      "\u001b[0;31mSystemError\u001b[0m: PyEval_EvalFrameEx returned a result with an error set",
      "\nThe above exception was the direct cause of the following exception:\n",
      "\u001b[0;31mSystemError\u001b[0m                               Traceback (most recent call last)",
      "\u001b[0;31mSystemError\u001b[0m: PyEval_EvalFrameEx returned a result with an error set",
      "\nThe above exception was the direct cause of the following exception:\n",
      "\u001b[0;31mSystemError\u001b[0m                               Traceback (most recent call last)",
      "\u001b[0;31mSystemError\u001b[0m: PyEval_EvalFrameEx returned a result with an error set",
      "\nThe above exception was the direct cause of the following exception:\n",
      "\u001b[0;31mSystemError\u001b[0m                               Traceback (most recent call last)",
      "\u001b[0;31mSystemError\u001b[0m: PyEval_EvalFrameEx returned a result with an error set",
      "\nThe above exception was the direct cause of the following exception:\n",
      "\u001b[0;31mSystemError\u001b[0m                               Traceback (most recent call last)",
      "\u001b[0;31mSystemError\u001b[0m: PyEval_EvalFrameEx returned a result with an error set",
      "\nThe above exception was the direct cause of the following exception:\n",
      "\u001b[0;31mSystemError\u001b[0m                               Traceback (most recent call last)",
      "\u001b[0;31mSystemError\u001b[0m: PyEval_EvalFrameEx returned a result with an error set",
      "\nThe above exception was the direct cause of the following exception:\n",
      "\u001b[0;31mSystemError\u001b[0m                               Traceback (most recent call last)",
      "\u001b[0;31mSystemError\u001b[0m: PyEval_EvalFrameEx returned a result with an error set",
      "\nThe above exception was the direct cause of the following exception:\n",
      "\u001b[0;31mSystemError\u001b[0m                               Traceback (most recent call last)",
      "\u001b[0;31mSystemError\u001b[0m: PyEval_EvalFrameEx returned a result with an error set",
      "\nThe above exception was the direct cause of the following exception:\n",
      "\u001b[0;31mSystemError\u001b[0m                               Traceback (most recent call last)",
      "\u001b[0;31mSystemError\u001b[0m: PyEval_EvalFrameEx returned a result with an error set",
      "\nThe above exception was the direct cause of the following exception:\n",
      "\u001b[0;31mSystemError\u001b[0m                               Traceback (most recent call last)",
      "\u001b[0;31mSystemError\u001b[0m: PyEval_EvalFrameEx returned a result with an error set",
      "\nThe above exception was the direct cause of the following exception:\n",
      "\u001b[0;31mSystemError\u001b[0m                               Traceback (most recent call last)",
      "\u001b[0;31mSystemError\u001b[0m: PyEval_EvalFrameEx returned a result with an error set",
      "\nThe above exception was the direct cause of the following exception:\n",
      "\u001b[0;31mSystemError\u001b[0m                               Traceback (most recent call last)",
      "\u001b[0;31mSystemError\u001b[0m: PyEval_EvalFrameEx returned a result with an error set",
      "\nThe above exception was the direct cause of the following exception:\n",
      "\u001b[0;31mSystemError\u001b[0m                               Traceback (most recent call last)",
      "\u001b[0;31mSystemError\u001b[0m: PyEval_EvalFrameEx returned a result with an error set",
      "\nThe above exception was the direct cause of the following exception:\n",
      "\u001b[0;31mSystemError\u001b[0m                               Traceback (most recent call last)",
      "\u001b[0;31mSystemError\u001b[0m: PyEval_EvalFrameEx returned a result with an error set",
      "\nThe above exception was the direct cause of the following exception:\n",
      "\u001b[0;31mSystemError\u001b[0m                               Traceback (most recent call last)",
      "\u001b[0;31mSystemError\u001b[0m: PyEval_EvalFrameEx returned a result with an error set",
      "\nThe above exception was the direct cause of the following exception:\n",
      "\u001b[0;31mSystemError\u001b[0m                               Traceback (most recent call last)",
      "\u001b[0;31mSystemError\u001b[0m: PyEval_EvalFrameEx returned a result with an error set",
      "\nThe above exception was the direct cause of the following exception:\n",
      "\u001b[0;31mSystemError\u001b[0m                               Traceback (most recent call last)",
      "\u001b[0;31mSystemError\u001b[0m: PyEval_EvalFrameEx returned a result with an error set",
      "\nThe above exception was the direct cause of the following exception:\n",
      "\u001b[0;31mSystemError\u001b[0m                               Traceback (most recent call last)",
      "\u001b[0;31mSystemError\u001b[0m: PyEval_EvalFrameEx returned a result with an error set",
      "\nThe above exception was the direct cause of the following exception:\n",
      "\u001b[0;31mSystemError\u001b[0m                               Traceback (most recent call last)",
      "\u001b[0;31mSystemError\u001b[0m: PyEval_EvalFrameEx returned a result with an error set",
      "\nThe above exception was the direct cause of the following exception:\n",
      "\u001b[0;31mSystemError\u001b[0m                               Traceback (most recent call last)",
      "\u001b[0;31mSystemError\u001b[0m: PyEval_EvalFrameEx returned a result with an error set",
      "\nThe above exception was the direct cause of the following exception:\n",
      "\u001b[0;31mSystemError\u001b[0m                               Traceback (most recent call last)",
      "\u001b[0;31mSystemError\u001b[0m: PyEval_EvalFrameEx returned a result with an error set",
      "\nThe above exception was the direct cause of the following exception:\n",
      "\u001b[0;31mSystemError\u001b[0m                               Traceback (most recent call last)",
      "\u001b[0;31mSystemError\u001b[0m: PyEval_EvalFrameEx returned a result with an error set",
      "\nThe above exception was the direct cause of the following exception:\n",
      "\u001b[0;31mSystemError\u001b[0m                               Traceback (most recent call last)",
      "\u001b[0;31mSystemError\u001b[0m: PyEval_EvalFrameEx returned a result with an error set",
      "\nThe above exception was the direct cause of the following exception:\n",
      "\u001b[0;31mSystemError\u001b[0m                               Traceback (most recent call last)",
      "\u001b[0;31mSystemError\u001b[0m: PyEval_EvalFrameEx returned a result with an error set",
      "\nThe above exception was the direct cause of the following exception:\n",
      "\u001b[0;31mSystemError\u001b[0m                               Traceback (most recent call last)",
      "\u001b[0;31mSystemError\u001b[0m: PyEval_EvalFrameEx returned a result with an error set",
      "\nThe above exception was the direct cause of the following exception:\n",
      "\u001b[0;31mSystemError\u001b[0m                               Traceback (most recent call last)",
      "\u001b[0;31mSystemError\u001b[0m: PyEval_EvalFrameEx returned a result with an error set",
      "\nThe above exception was the direct cause of the following exception:\n",
      "\u001b[0;31mSystemError\u001b[0m                               Traceback (most recent call last)",
      "\u001b[0;31mSystemError\u001b[0m: PyEval_EvalFrameEx returned a result with an error set",
      "\nThe above exception was the direct cause of the following exception:\n",
      "\u001b[0;31mSystemError\u001b[0m                               Traceback (most recent call last)",
      "\u001b[0;31mSystemError\u001b[0m: PyEval_EvalFrameEx returned a result with an error set",
      "\nThe above exception was the direct cause of the following exception:\n",
      "\u001b[0;31mSystemError\u001b[0m                               Traceback (most recent call last)",
      "\u001b[0;31mSystemError\u001b[0m: PyEval_EvalFrameEx returned a result with an error set",
      "\nThe above exception was the direct cause of the following exception:\n",
      "\u001b[0;31mSystemError\u001b[0m                               Traceback (most recent call last)",
      "\u001b[0;31mSystemError\u001b[0m: PyEval_EvalFrameEx returned a result with an error set",
      "\nThe above exception was the direct cause of the following exception:\n",
      "\u001b[0;31mSystemError\u001b[0m                               Traceback (most recent call last)",
      "\u001b[0;31mSystemError\u001b[0m: PyEval_EvalFrameEx returned a result with an error set",
      "\nThe above exception was the direct cause of the following exception:\n",
      "\u001b[0;31mSystemError\u001b[0m                               Traceback (most recent call last)",
      "\u001b[0;31mSystemError\u001b[0m: PyEval_EvalFrameEx returned a result with an error set",
      "\nThe above exception was the direct cause of the following exception:\n",
      "\u001b[0;31mSystemError\u001b[0m                               Traceback (most recent call last)",
      "\u001b[0;31mSystemError\u001b[0m: PyEval_EvalFrameEx returned a result with an error set",
      "\nThe above exception was the direct cause of the following exception:\n",
      "\u001b[0;31mSystemError\u001b[0m                               Traceback (most recent call last)",
      "\u001b[0;31mSystemError\u001b[0m: PyEval_EvalFrameEx returned a result with an error set",
      "\nThe above exception was the direct cause of the following exception:\n",
      "\u001b[0;31mSystemError\u001b[0m                               Traceback (most recent call last)",
      "\u001b[0;31mSystemError\u001b[0m: PyEval_EvalFrameEx returned a result with an error set",
      "\nThe above exception was the direct cause of the following exception:\n",
      "\u001b[0;31mSystemError\u001b[0m                               Traceback (most recent call last)",
      "\u001b[0;31mSystemError\u001b[0m: PyEval_EvalFrameEx returned a result with an error set",
      "\nThe above exception was the direct cause of the following exception:\n",
      "\u001b[0;31mSystemError\u001b[0m                               Traceback (most recent call last)",
      "\u001b[0;31mSystemError\u001b[0m: PyEval_EvalFrameEx returned a result with an error set",
      "\nThe above exception was the direct cause of the following exception:\n",
      "\u001b[0;31mSystemError\u001b[0m                               Traceback (most recent call last)",
      "\u001b[0;31mSystemError\u001b[0m: PyEval_EvalFrameEx returned a result with an error set",
      "\nThe above exception was the direct cause of the following exception:\n",
      "\u001b[0;31mSystemError\u001b[0m                               Traceback (most recent call last)",
      "\u001b[0;31mSystemError\u001b[0m: PyEval_EvalFrameEx returned a result with an error set",
      "\nThe above exception was the direct cause of the following exception:\n",
      "\u001b[0;31mSystemError\u001b[0m                               Traceback (most recent call last)",
      "\u001b[0;31mSystemError\u001b[0m: PyEval_EvalFrameEx returned a result with an error set",
      "\nThe above exception was the direct cause of the following exception:\n",
      "\u001b[0;31mSystemError\u001b[0m                               Traceback (most recent call last)",
      "\u001b[0;31mSystemError\u001b[0m: PyEval_EvalFrameEx returned a result with an error set",
      "\nThe above exception was the direct cause of the following exception:\n",
      "\u001b[0;31mSystemError\u001b[0m                               Traceback (most recent call last)",
      "\u001b[0;31mSystemError\u001b[0m: PyEval_EvalFrameEx returned a result with an error set",
      "\nThe above exception was the direct cause of the following exception:\n",
      "\u001b[0;31mSystemError\u001b[0m                               Traceback (most recent call last)",
      "\u001b[0;31mSystemError\u001b[0m: PyEval_EvalFrameEx returned a result with an error set",
      "\nThe above exception was the direct cause of the following exception:\n",
      "\u001b[0;31mSystemError\u001b[0m                               Traceback (most recent call last)",
      "\u001b[0;31mSystemError\u001b[0m: PyEval_EvalFrameEx returned a result with an error set",
      "\nThe above exception was the direct cause of the following exception:\n",
      "\u001b[0;31mSystemError\u001b[0m                               Traceback (most recent call last)",
      "\u001b[0;31mSystemError\u001b[0m: PyEval_EvalFrameEx returned a result with an error set",
      "\nThe above exception was the direct cause of the following exception:\n",
      "\u001b[0;31mSystemError\u001b[0m                               Traceback (most recent call last)",
      "\u001b[0;31mSystemError\u001b[0m: PyEval_EvalFrameEx returned a result with an error set",
      "\nThe above exception was the direct cause of the following exception:\n",
      "\u001b[0;31mSystemError\u001b[0m                               Traceback (most recent call last)",
      "\u001b[0;31mSystemError\u001b[0m: PyEval_EvalFrameEx returned a result with an error set",
      "\nThe above exception was the direct cause of the following exception:\n",
      "\u001b[0;31mSystemError\u001b[0m                               Traceback (most recent call last)",
      "\u001b[0;31mSystemError\u001b[0m: PyEval_EvalFrameEx returned a result with an error set",
      "\nThe above exception was the direct cause of the following exception:\n",
      "\u001b[0;31mSystemError\u001b[0m                               Traceback (most recent call last)",
      "\u001b[0;31mSystemError\u001b[0m: PyEval_EvalFrameEx returned a result with an error set",
      "\nThe above exception was the direct cause of the following exception:\n",
      "\u001b[0;31mSystemError\u001b[0m                               Traceback (most recent call last)",
      "\u001b[0;31mSystemError\u001b[0m: PyEval_EvalFrameEx returned a result with an error set",
      "\nThe above exception was the direct cause of the following exception:\n",
      "\u001b[0;31mSystemError\u001b[0m                               Traceback (most recent call last)",
      "\u001b[0;31mSystemError\u001b[0m: PyEval_EvalFrameEx returned a result with an error set",
      "\nThe above exception was the direct cause of the following exception:\n",
      "\u001b[0;31mSystemError\u001b[0m                               Traceback (most recent call last)",
      "\u001b[0;31mSystemError\u001b[0m: PyEval_EvalFrameEx returned a result with an error set",
      "\nThe above exception was the direct cause of the following exception:\n",
      "\u001b[0;31mSystemError\u001b[0m                               Traceback (most recent call last)",
      "\u001b[0;31mSystemError\u001b[0m: PyEval_EvalFrameEx returned a result with an error set",
      "\nThe above exception was the direct cause of the following exception:\n",
      "\u001b[0;31mSystemError\u001b[0m                               Traceback (most recent call last)",
      "\u001b[0;31mSystemError\u001b[0m: PyEval_EvalFrameEx returned a result with an error set",
      "\nThe above exception was the direct cause of the following exception:\n",
      "\u001b[0;31mSystemError\u001b[0m                               Traceback (most recent call last)",
      "\u001b[0;31mSystemError\u001b[0m: PyEval_EvalFrameEx returned a result with an error set",
      "\nThe above exception was the direct cause of the following exception:\n",
      "\u001b[0;31mSystemError\u001b[0m                               Traceback (most recent call last)",
      "\u001b[0;31mSystemError\u001b[0m: PyEval_EvalFrameEx returned a result with an error set",
      "\nThe above exception was the direct cause of the following exception:\n",
      "\u001b[0;31mSystemError\u001b[0m                               Traceback (most recent call last)",
      "\u001b[0;31mSystemError\u001b[0m: PyEval_EvalFrameEx returned a result with an error set",
      "\nThe above exception was the direct cause of the following exception:\n",
      "\u001b[0;31mSystemError\u001b[0m                               Traceback (most recent call last)",
      "\u001b[0;31mSystemError\u001b[0m: PyEval_EvalFrameEx returned a result with an error set",
      "\nThe above exception was the direct cause of the following exception:\n",
      "\u001b[0;31mSystemError\u001b[0m                               Traceback (most recent call last)",
      "\u001b[0;31mSystemError\u001b[0m: PyEval_EvalFrameEx returned a result with an error set",
      "\nThe above exception was the direct cause of the following exception:\n",
      "\u001b[0;31mSystemError\u001b[0m                               Traceback (most recent call last)",
      "\u001b[0;31mSystemError\u001b[0m: PyEval_EvalFrameEx returned a result with an error set",
      "\nThe above exception was the direct cause of the following exception:\n",
      "\u001b[0;31mSystemError\u001b[0m                               Traceback (most recent call last)",
      "\u001b[0;31mSystemError\u001b[0m: PyEval_EvalFrameEx returned a result with an error set",
      "\nThe above exception was the direct cause of the following exception:\n",
      "\u001b[0;31mSystemError\u001b[0m                               Traceback (most recent call last)",
      "\u001b[0;31mSystemError\u001b[0m: PyEval_EvalFrameEx returned a result with an error set",
      "\nThe above exception was the direct cause of the following exception:\n",
      "\u001b[0;31mSystemError\u001b[0m                               Traceback (most recent call last)",
      "\u001b[0;31mSystemError\u001b[0m: PyEval_EvalFrameEx returned a result with an error set",
      "\nThe above exception was the direct cause of the following exception:\n",
      "\u001b[0;31mSystemError\u001b[0m                               Traceback (most recent call last)",
      "\u001b[0;31mSystemError\u001b[0m: PyEval_EvalFrameEx returned a result with an error set",
      "\nThe above exception was the direct cause of the following exception:\n",
      "\u001b[0;31mSystemError\u001b[0m                               Traceback (most recent call last)",
      "\u001b[0;31mSystemError\u001b[0m: PyEval_EvalFrameEx returned a result with an error set",
      "\nThe above exception was the direct cause of the following exception:\n",
      "\u001b[0;31mSystemError\u001b[0m                               Traceback (most recent call last)",
      "\u001b[0;31mSystemError\u001b[0m: PyEval_EvalFrameEx returned a result with an error set",
      "\nThe above exception was the direct cause of the following exception:\n",
      "\u001b[0;31mSystemError\u001b[0m                               Traceback (most recent call last)",
      "\u001b[0;31mSystemError\u001b[0m: PyEval_EvalFrameEx returned a result with an error set",
      "\nThe above exception was the direct cause of the following exception:\n",
      "\u001b[0;31mSystemError\u001b[0m                               Traceback (most recent call last)",
      "\u001b[0;31mSystemError\u001b[0m: PyEval_EvalFrameEx returned a result with an error set",
      "\nThe above exception was the direct cause of the following exception:\n",
      "\u001b[0;31mSystemError\u001b[0m                               Traceback (most recent call last)",
      "\u001b[0;31mSystemError\u001b[0m: PyEval_EvalFrameEx returned a result with an error set",
      "\nThe above exception was the direct cause of the following exception:\n",
      "\u001b[0;31mSystemError\u001b[0m                               Traceback (most recent call last)",
      "\u001b[0;31mSystemError\u001b[0m: PyEval_EvalFrameEx returned a result with an error set",
      "\nThe above exception was the direct cause of the following exception:\n",
      "\u001b[0;31mSystemError\u001b[0m                               Traceback (most recent call last)",
      "\u001b[0;31mSystemError\u001b[0m: PyEval_EvalFrameEx returned a result with an error set",
      "\nThe above exception was the direct cause of the following exception:\n",
      "\u001b[0;31mSystemError\u001b[0m                               Traceback (most recent call last)",
      "\u001b[0;31mSystemError\u001b[0m: PyEval_EvalFrameEx returned a result with an error set",
      "\nThe above exception was the direct cause of the following exception:\n",
      "\u001b[0;31mSystemError\u001b[0m                               Traceback (most recent call last)",
      "\u001b[0;31mSystemError\u001b[0m: PyEval_EvalFrameEx returned a result with an error set",
      "\nThe above exception was the direct cause of the following exception:\n",
      "\u001b[0;31mSystemError\u001b[0m                               Traceback (most recent call last)",
      "\u001b[0;31mSystemError\u001b[0m: PyEval_EvalFrameEx returned a result with an error set",
      "\nThe above exception was the direct cause of the following exception:\n",
      "\u001b[0;31mSystemError\u001b[0m                               Traceback (most recent call last)",
      "\u001b[0;31mSystemError\u001b[0m: PyEval_EvalFrameEx returned a result with an error set",
      "\nThe above exception was the direct cause of the following exception:\n",
      "\u001b[0;31mSystemError\u001b[0m                               Traceback (most recent call last)",
      "\u001b[0;31mSystemError\u001b[0m: PyEval_EvalFrameEx returned a result with an error set",
      "\nThe above exception was the direct cause of the following exception:\n",
      "\u001b[0;31mSystemError\u001b[0m                               Traceback (most recent call last)",
      "\u001b[0;31mSystemError\u001b[0m: PyEval_EvalFrameEx returned a result with an error set",
      "\nThe above exception was the direct cause of the following exception:\n",
      "\u001b[0;31mSystemError\u001b[0m                               Traceback (most recent call last)",
      "\u001b[0;31mSystemError\u001b[0m: PyEval_EvalFrameEx returned a result with an error set",
      "\nThe above exception was the direct cause of the following exception:\n",
      "\u001b[0;31mSystemError\u001b[0m                               Traceback (most recent call last)",
      "\u001b[0;31mSystemError\u001b[0m: PyEval_EvalFrameEx returned a result with an error set",
      "\nThe above exception was the direct cause of the following exception:\n",
      "\u001b[0;31mSystemError\u001b[0m                               Traceback (most recent call last)",
      "\u001b[0;31mSystemError\u001b[0m: PyEval_EvalFrameEx returned a result with an error set",
      "\nThe above exception was the direct cause of the following exception:\n",
      "\u001b[0;31mSystemError\u001b[0m                               Traceback (most recent call last)",
      "\u001b[0;31mSystemError\u001b[0m: PyEval_EvalFrameEx returned a result with an error set",
      "\nThe above exception was the direct cause of the following exception:\n",
      "\u001b[0;31mSystemError\u001b[0m                               Traceback (most recent call last)",
      "\u001b[0;31mSystemError\u001b[0m: PyEval_EvalFrameEx returned a result with an error set",
      "\nThe above exception was the direct cause of the following exception:\n",
      "\u001b[0;31mSystemError\u001b[0m                               Traceback (most recent call last)",
      "\u001b[0;31mSystemError\u001b[0m: PyEval_EvalFrameEx returned a result with an error set",
      "\nThe above exception was the direct cause of the following exception:\n",
      "\u001b[0;31mSystemError\u001b[0m                               Traceback (most recent call last)",
      "\u001b[0;31mSystemError\u001b[0m: PyEval_EvalFrameEx returned a result with an error set",
      "\nThe above exception was the direct cause of the following exception:\n",
      "\u001b[0;31mSystemError\u001b[0m                               Traceback (most recent call last)",
      "\u001b[0;31mSystemError\u001b[0m: PyEval_EvalFrameEx returned a result with an error set",
      "\nThe above exception was the direct cause of the following exception:\n",
      "\u001b[0;31mSystemError\u001b[0m                               Traceback (most recent call last)",
      "\u001b[0;31mSystemError\u001b[0m: PyEval_EvalFrameEx returned a result with an error set",
      "\nThe above exception was the direct cause of the following exception:\n",
      "\u001b[0;31mSystemError\u001b[0m                               Traceback (most recent call last)",
      "\u001b[0;31mSystemError\u001b[0m: PyEval_EvalFrameEx returned a result with an error set",
      "\nThe above exception was the direct cause of the following exception:\n",
      "\u001b[0;31mSystemError\u001b[0m                               Traceback (most recent call last)",
      "\u001b[0;31mSystemError\u001b[0m: PyEval_EvalFrameEx returned a result with an error set",
      "\nThe above exception was the direct cause of the following exception:\n",
      "\u001b[0;31mSystemError\u001b[0m                               Traceback (most recent call last)",
      "\u001b[0;31mSystemError\u001b[0m: PyEval_EvalFrameEx returned a result with an error set",
      "\nThe above exception was the direct cause of the following exception:\n",
      "\u001b[0;31mSystemError\u001b[0m                               Traceback (most recent call last)",
      "\u001b[0;31mSystemError\u001b[0m: PyEval_EvalFrameEx returned a result with an error set",
      "\nThe above exception was the direct cause of the following exception:\n",
      "\u001b[0;31mSystemError\u001b[0m                               Traceback (most recent call last)",
      "\u001b[0;31mSystemError\u001b[0m: PyEval_EvalFrameEx returned a result with an error set",
      "\nThe above exception was the direct cause of the following exception:\n",
      "\u001b[0;31mSystemError\u001b[0m                               Traceback (most recent call last)",
      "\u001b[0;31mSystemError\u001b[0m: PyEval_EvalFrameEx returned a result with an error set",
      "\nThe above exception was the direct cause of the following exception:\n",
      "\u001b[0;31mSystemError\u001b[0m                               Traceback (most recent call last)",
      "\u001b[0;31mSystemError\u001b[0m: PyEval_EvalFrameEx returned a result with an error set",
      "\nThe above exception was the direct cause of the following exception:\n",
      "\u001b[0;31mSystemError\u001b[0m                               Traceback (most recent call last)",
      "\u001b[0;31mSystemError\u001b[0m: PyEval_EvalFrameEx returned a result with an error set",
      "\nThe above exception was the direct cause of the following exception:\n",
      "\u001b[0;31mSystemError\u001b[0m                               Traceback (most recent call last)",
      "\u001b[0;31mSystemError\u001b[0m: PyEval_EvalFrameEx returned a result with an error set",
      "\nThe above exception was the direct cause of the following exception:\n",
      "\u001b[0;31mSystemError\u001b[0m                               Traceback (most recent call last)",
      "\u001b[0;31mSystemError\u001b[0m: PyEval_EvalFrameEx returned a result with an error set",
      "\nThe above exception was the direct cause of the following exception:\n",
      "\u001b[0;31mSystemError\u001b[0m                               Traceback (most recent call last)",
      "\u001b[0;31mSystemError\u001b[0m: PyEval_EvalFrameEx returned a result with an error set",
      "\nThe above exception was the direct cause of the following exception:\n",
      "\u001b[0;31mSystemError\u001b[0m                               Traceback (most recent call last)",
      "\u001b[0;31mSystemError\u001b[0m: PyEval_EvalFrameEx returned a result with an error set",
      "\nThe above exception was the direct cause of the following exception:\n",
      "\u001b[0;31mSystemError\u001b[0m                               Traceback (most recent call last)",
      "\u001b[0;31mSystemError\u001b[0m: PyEval_EvalFrameEx returned a result with an error set",
      "\nThe above exception was the direct cause of the following exception:\n",
      "\u001b[0;31mSystemError\u001b[0m                               Traceback (most recent call last)",
      "\u001b[0;31mSystemError\u001b[0m: PyEval_EvalFrameEx returned a result with an error set",
      "\nThe above exception was the direct cause of the following exception:\n",
      "\u001b[0;31mSystemError\u001b[0m                               Traceback (most recent call last)",
      "\u001b[0;31mSystemError\u001b[0m: PyEval_EvalFrameEx returned a result with an error set",
      "\nThe above exception was the direct cause of the following exception:\n",
      "\u001b[0;31mSystemError\u001b[0m                               Traceback (most recent call last)",
      "\u001b[0;31mSystemError\u001b[0m: PyEval_EvalFrameEx returned a result with an error set",
      "\nThe above exception was the direct cause of the following exception:\n",
      "\u001b[0;31mSystemError\u001b[0m                               Traceback (most recent call last)",
      "\u001b[0;31mSystemError\u001b[0m: PyEval_EvalFrameEx returned a result with an error set",
      "\nThe above exception was the direct cause of the following exception:\n",
      "\u001b[0;31mSystemError\u001b[0m                               Traceback (most recent call last)",
      "\u001b[0;31mSystemError\u001b[0m: PyEval_EvalFrameEx returned a result with an error set",
      "\nThe above exception was the direct cause of the following exception:\n",
      "\u001b[0;31mSystemError\u001b[0m                               Traceback (most recent call last)",
      "\u001b[0;31mSystemError\u001b[0m: PyEval_EvalFrameEx returned a result with an error set",
      "\nThe above exception was the direct cause of the following exception:\n",
      "\u001b[0;31mSystemError\u001b[0m                               Traceback (most recent call last)",
      "\u001b[0;31mSystemError\u001b[0m: PyEval_EvalFrameEx returned a result with an error set",
      "\nThe above exception was the direct cause of the following exception:\n",
      "\u001b[0;31mSystemError\u001b[0m                               Traceback (most recent call last)",
      "\u001b[0;31mSystemError\u001b[0m: PyEval_EvalFrameEx returned a result with an error set",
      "\nThe above exception was the direct cause of the following exception:\n",
      "\u001b[0;31mSystemError\u001b[0m                               Traceback (most recent call last)",
      "\u001b[0;31mSystemError\u001b[0m: PyEval_EvalFrameEx returned a result with an error set",
      "\nThe above exception was the direct cause of the following exception:\n",
      "\u001b[0;31mSystemError\u001b[0m                               Traceback (most recent call last)",
      "\u001b[0;31mSystemError\u001b[0m: PyEval_EvalFrameEx returned a result with an error set",
      "\nThe above exception was the direct cause of the following exception:\n",
      "\u001b[0;31mSystemError\u001b[0m                               Traceback (most recent call last)",
      "\u001b[0;31mSystemError\u001b[0m: PyEval_EvalFrameEx returned a result with an error set",
      "\nThe above exception was the direct cause of the following exception:\n",
      "\u001b[0;31mSystemError\u001b[0m                               Traceback (most recent call last)",
      "\u001b[0;31mSystemError\u001b[0m: PyEval_EvalFrameEx returned a result with an error set",
      "\nThe above exception was the direct cause of the following exception:\n",
      "\u001b[0;31mSystemError\u001b[0m                               Traceback (most recent call last)",
      "\u001b[0;31mSystemError\u001b[0m: PyEval_EvalFrameEx returned a result with an error set",
      "\nThe above exception was the direct cause of the following exception:\n",
      "\u001b[0;31mSystemError\u001b[0m                               Traceback (most recent call last)",
      "\u001b[0;31mSystemError\u001b[0m: PyEval_EvalFrameEx returned a result with an error set",
      "\nThe above exception was the direct cause of the following exception:\n",
      "\u001b[0;31mSystemError\u001b[0m                               Traceback (most recent call last)",
      "\u001b[0;31mSystemError\u001b[0m: PyEval_EvalFrameEx returned a result with an error set",
      "\nThe above exception was the direct cause of the following exception:\n",
      "\u001b[0;31mSystemError\u001b[0m                               Traceback (most recent call last)",
      "\u001b[0;31mSystemError\u001b[0m: PyEval_EvalFrameEx returned a result with an error set",
      "\nThe above exception was the direct cause of the following exception:\n",
      "\u001b[0;31mSystemError\u001b[0m                               Traceback (most recent call last)",
      "\u001b[0;31mSystemError\u001b[0m: PyEval_EvalFrameEx returned a result with an error set",
      "\nThe above exception was the direct cause of the following exception:\n",
      "\u001b[0;31mSystemError\u001b[0m                               Traceback (most recent call last)",
      "\u001b[0;31mSystemError\u001b[0m: PyEval_EvalFrameEx returned a result with an error set",
      "\nThe above exception was the direct cause of the following exception:\n",
      "\u001b[0;31mSystemError\u001b[0m                               Traceback (most recent call last)",
      "\u001b[0;31mSystemError\u001b[0m: PyEval_EvalFrameEx returned a result with an error set",
      "\nThe above exception was the direct cause of the following exception:\n",
      "\u001b[0;31mSystemError\u001b[0m                               Traceback (most recent call last)",
      "\u001b[0;31mSystemError\u001b[0m: PyEval_EvalFrameEx returned a result with an error set",
      "\nThe above exception was the direct cause of the following exception:\n",
      "\u001b[0;31mSystemError\u001b[0m                               Traceback (most recent call last)",
      "\u001b[0;31mSystemError\u001b[0m: PyEval_EvalFrameEx returned a result with an error set",
      "\nThe above exception was the direct cause of the following exception:\n",
      "\u001b[0;31mSystemError\u001b[0m                               Traceback (most recent call last)",
      "\u001b[0;31mSystemError\u001b[0m: PyEval_EvalFrameEx returned a result with an error set",
      "\nThe above exception was the direct cause of the following exception:\n",
      "\u001b[0;31mSystemError\u001b[0m                               Traceback (most recent call last)",
      "\u001b[0;31mSystemError\u001b[0m: PyEval_EvalFrameEx returned a result with an error set",
      "\nThe above exception was the direct cause of the following exception:\n",
      "\u001b[0;31mSystemError\u001b[0m                               Traceback (most recent call last)",
      "\u001b[0;31mSystemError\u001b[0m: PyEval_EvalFrameEx returned a result with an error set",
      "\nThe above exception was the direct cause of the following exception:\n",
      "\u001b[0;31mSystemError\u001b[0m                               Traceback (most recent call last)",
      "\u001b[0;31mSystemError\u001b[0m: PyEval_EvalFrameEx returned a result with an error set",
      "\nThe above exception was the direct cause of the following exception:\n",
      "\u001b[0;31mSystemError\u001b[0m                               Traceback (most recent call last)",
      "\u001b[0;31mSystemError\u001b[0m: PyEval_EvalFrameEx returned a result with an error set",
      "\nThe above exception was the direct cause of the following exception:\n",
      "\u001b[0;31mSystemError\u001b[0m                               Traceback (most recent call last)",
      "\u001b[0;31mSystemError\u001b[0m: PyEval_EvalFrameEx returned a result with an error set",
      "\nThe above exception was the direct cause of the following exception:\n",
      "\u001b[0;31mSystemError\u001b[0m                               Traceback (most recent call last)",
      "\u001b[0;31mSystemError\u001b[0m: PyEval_EvalFrameEx returned a result with an error set",
      "\nThe above exception was the direct cause of the following exception:\n",
      "\u001b[0;31mSystemError\u001b[0m                               Traceback (most recent call last)",
      "\u001b[0;31mSystemError\u001b[0m: PyEval_EvalFrameEx returned a result with an error set",
      "\nThe above exception was the direct cause of the following exception:\n",
      "\u001b[0;31mSystemError\u001b[0m                               Traceback (most recent call last)",
      "\u001b[0;31mSystemError\u001b[0m: PyEval_EvalFrameEx returned a result with an error set",
      "\nThe above exception was the direct cause of the following exception:\n",
      "\u001b[0;31mSystemError\u001b[0m                               Traceback (most recent call last)",
      "\u001b[0;31mSystemError\u001b[0m: PyEval_EvalFrameEx returned a result with an error set",
      "\nThe above exception was the direct cause of the following exception:\n",
      "\u001b[0;31mSystemError\u001b[0m                               Traceback (most recent call last)",
      "\u001b[0;31mSystemError\u001b[0m: PyEval_EvalFrameEx returned a result with an error set",
      "\nThe above exception was the direct cause of the following exception:\n",
      "\u001b[0;31mSystemError\u001b[0m                               Traceback (most recent call last)",
      "\u001b[0;31mSystemError\u001b[0m: PyEval_EvalFrameEx returned a result with an error set",
      "\nThe above exception was the direct cause of the following exception:\n",
      "\u001b[0;31mSystemError\u001b[0m                               Traceback (most recent call last)",
      "\u001b[0;31mSystemError\u001b[0m: PyEval_EvalFrameEx returned a result with an error set",
      "\nThe above exception was the direct cause of the following exception:\n",
      "\u001b[0;31mSystemError\u001b[0m                               Traceback (most recent call last)",
      "\u001b[0;31mSystemError\u001b[0m: PyEval_EvalFrameEx returned a result with an error set",
      "\nThe above exception was the direct cause of the following exception:\n",
      "\u001b[0;31mSystemError\u001b[0m                               Traceback (most recent call last)",
      "\u001b[0;31mSystemError\u001b[0m: PyEval_EvalFrameEx returned a result with an error set",
      "\nThe above exception was the direct cause of the following exception:\n",
      "\u001b[0;31mSystemError\u001b[0m                               Traceback (most recent call last)",
      "\u001b[0;31mSystemError\u001b[0m: PyEval_EvalFrameEx returned a result with an error set",
      "\nThe above exception was the direct cause of the following exception:\n",
      "\u001b[0;31mSystemError\u001b[0m                               Traceback (most recent call last)",
      "\u001b[0;31mSystemError\u001b[0m: PyEval_EvalFrameEx returned a result with an error set",
      "\nThe above exception was the direct cause of the following exception:\n",
      "\u001b[0;31mSystemError\u001b[0m                               Traceback (most recent call last)",
      "\u001b[0;31mSystemError\u001b[0m: PyEval_EvalFrameEx returned a result with an error set",
      "\nThe above exception was the direct cause of the following exception:\n",
      "\u001b[0;31mSystemError\u001b[0m                               Traceback (most recent call last)",
      "\u001b[0;31mSystemError\u001b[0m: PyEval_EvalFrameEx returned a result with an error set",
      "\nThe above exception was the direct cause of the following exception:\n",
      "\u001b[0;31mSystemError\u001b[0m                               Traceback (most recent call last)",
      "\u001b[0;31mSystemError\u001b[0m: PyEval_EvalFrameEx returned a result with an error set",
      "\nThe above exception was the direct cause of the following exception:\n",
      "\u001b[0;31mSystemError\u001b[0m                               Traceback (most recent call last)",
      "\u001b[0;31mSystemError\u001b[0m: PyEval_EvalFrameEx returned a result with an error set",
      "\nThe above exception was the direct cause of the following exception:\n",
      "\u001b[0;31mSystemError\u001b[0m                               Traceback (most recent call last)",
      "\u001b[0;31mSystemError\u001b[0m: PyEval_EvalFrameEx returned a result with an error set",
      "\nThe above exception was the direct cause of the following exception:\n",
      "\u001b[0;31mSystemError\u001b[0m                               Traceback (most recent call last)",
      "\u001b[0;31mSystemError\u001b[0m: PyEval_EvalFrameEx returned a result with an error set",
      "\nThe above exception was the direct cause of the following exception:\n",
      "\u001b[0;31mSystemError\u001b[0m                               Traceback (most recent call last)",
      "\u001b[0;31mSystemError\u001b[0m: PyEval_EvalFrameEx returned a result with an error set",
      "\nThe above exception was the direct cause of the following exception:\n",
      "\u001b[0;31mSystemError\u001b[0m                               Traceback (most recent call last)",
      "\u001b[0;31mSystemError\u001b[0m: PyEval_EvalFrameEx returned a result with an error set",
      "\nThe above exception was the direct cause of the following exception:\n",
      "\u001b[0;31mSystemError\u001b[0m                               Traceback (most recent call last)",
      "\u001b[0;31mSystemError\u001b[0m: PyEval_EvalFrameEx returned a result with an error set",
      "\nThe above exception was the direct cause of the following exception:\n",
      "\u001b[0;31mSystemError\u001b[0m                               Traceback (most recent call last)",
      "\u001b[0;31mSystemError\u001b[0m: PyEval_EvalFrameEx returned a result with an error set",
      "\nThe above exception was the direct cause of the following exception:\n",
      "\u001b[0;31mSystemError\u001b[0m                               Traceback (most recent call last)",
      "\u001b[0;31mSystemError\u001b[0m: PyEval_EvalFrameEx returned a result with an error set",
      "\nThe above exception was the direct cause of the following exception:\n",
      "\u001b[0;31mSystemError\u001b[0m                               Traceback (most recent call last)",
      "\u001b[0;31mSystemError\u001b[0m: PyEval_EvalFrameEx returned a result with an error set",
      "\nThe above exception was the direct cause of the following exception:\n",
      "\u001b[0;31mSystemError\u001b[0m                               Traceback (most recent call last)",
      "\u001b[0;31mSystemError\u001b[0m: PyEval_EvalFrameEx returned a result with an error set",
      "\nThe above exception was the direct cause of the following exception:\n",
      "\u001b[0;31mSystemError\u001b[0m                               Traceback (most recent call last)",
      "\u001b[0;31mSystemError\u001b[0m: PyEval_EvalFrameEx returned a result with an error set",
      "\nThe above exception was the direct cause of the following exception:\n",
      "\u001b[0;31mSystemError\u001b[0m                               Traceback (most recent call last)",
      "\u001b[0;31mSystemError\u001b[0m: PyEval_EvalFrameEx returned a result with an error set",
      "\nThe above exception was the direct cause of the following exception:\n",
      "\u001b[0;31mSystemError\u001b[0m                               Traceback (most recent call last)",
      "\u001b[0;31mSystemError\u001b[0m: PyEval_EvalFrameEx returned a result with an error set",
      "\nThe above exception was the direct cause of the following exception:\n",
      "\u001b[0;31mSystemError\u001b[0m                               Traceback (most recent call last)",
      "\u001b[0;31mSystemError\u001b[0m: PyEval_EvalFrameEx returned a result with an error set",
      "\nThe above exception was the direct cause of the following exception:\n",
      "\u001b[0;31mSystemError\u001b[0m                               Traceback (most recent call last)",
      "\u001b[0;31mSystemError\u001b[0m: PyEval_EvalFrameEx returned a result with an error set",
      "\nThe above exception was the direct cause of the following exception:\n",
      "\u001b[0;31mSystemError\u001b[0m                               Traceback (most recent call last)",
      "\u001b[0;31mSystemError\u001b[0m: PyEval_EvalFrameEx returned a result with an error set",
      "\nThe above exception was the direct cause of the following exception:\n",
      "\u001b[0;31mSystemError\u001b[0m                               Traceback (most recent call last)",
      "\u001b[0;31mSystemError\u001b[0m: PyEval_EvalFrameEx returned a result with an error set",
      "\nThe above exception was the direct cause of the following exception:\n",
      "\u001b[0;31mSystemError\u001b[0m                               Traceback (most recent call last)",
      "\u001b[0;31mSystemError\u001b[0m: PyEval_EvalFrameEx returned a result with an error set",
      "\nThe above exception was the direct cause of the following exception:\n",
      "\u001b[0;31mSystemError\u001b[0m                               Traceback (most recent call last)",
      "\u001b[0;31mSystemError\u001b[0m: PyEval_EvalFrameEx returned a result with an error set",
      "\nThe above exception was the direct cause of the following exception:\n",
      "\u001b[0;31mSystemError\u001b[0m                               Traceback (most recent call last)",
      "\u001b[0;31mSystemError\u001b[0m: PyEval_EvalFrameEx returned a result with an error set",
      "\nThe above exception was the direct cause of the following exception:\n",
      "\u001b[0;31mSystemError\u001b[0m                               Traceback (most recent call last)",
      "\u001b[0;31mSystemError\u001b[0m: PyEval_EvalFrameEx returned a result with an error set",
      "\nThe above exception was the direct cause of the following exception:\n",
      "\u001b[0;31mSystemError\u001b[0m                               Traceback (most recent call last)",
      "\u001b[0;31mSystemError\u001b[0m: PyEval_EvalFrameEx returned a result with an error set",
      "\nThe above exception was the direct cause of the following exception:\n",
      "\u001b[0;31mSystemError\u001b[0m                               Traceback (most recent call last)",
      "\u001b[0;31mSystemError\u001b[0m: PyEval_EvalFrameEx returned a result with an error set",
      "\nThe above exception was the direct cause of the following exception:\n",
      "\u001b[0;31mSystemError\u001b[0m                               Traceback (most recent call last)",
      "\u001b[0;31mSystemError\u001b[0m: PyEval_EvalFrameEx returned a result with an error set",
      "\nThe above exception was the direct cause of the following exception:\n",
      "\u001b[0;31mSystemError\u001b[0m                               Traceback (most recent call last)",
      "\u001b[0;31mSystemError\u001b[0m: PyEval_EvalFrameEx returned a result with an error set",
      "\nThe above exception was the direct cause of the following exception:\n",
      "\u001b[0;31mSystemError\u001b[0m                               Traceback (most recent call last)",
      "\u001b[0;31mSystemError\u001b[0m: PyEval_EvalFrameEx returned a result with an error set",
      "\nThe above exception was the direct cause of the following exception:\n",
      "\u001b[0;31mSystemError\u001b[0m                               Traceback (most recent call last)",
      "\u001b[0;31mSystemError\u001b[0m: PyEval_EvalFrameEx returned a result with an error set",
      "\nThe above exception was the direct cause of the following exception:\n",
      "\u001b[0;31mSystemError\u001b[0m                               Traceback (most recent call last)",
      "\u001b[0;31mSystemError\u001b[0m: PyEval_EvalFrameEx returned a result with an error set",
      "\nThe above exception was the direct cause of the following exception:\n",
      "\u001b[0;31mSystemError\u001b[0m                               Traceback (most recent call last)",
      "\u001b[0;31mSystemError\u001b[0m: PyEval_EvalFrameEx returned a result with an error set",
      "\nThe above exception was the direct cause of the following exception:\n",
      "\u001b[0;31mSystemError\u001b[0m                               Traceback (most recent call last)",
      "\u001b[0;31mSystemError\u001b[0m: PyEval_EvalFrameEx returned a result with an error set",
      "\nThe above exception was the direct cause of the following exception:\n",
      "\u001b[0;31mSystemError\u001b[0m                               Traceback (most recent call last)",
      "\u001b[0;31mSystemError\u001b[0m: PyEval_EvalFrameEx returned a result with an error set",
      "\nThe above exception was the direct cause of the following exception:\n",
      "\u001b[0;31mSystemError\u001b[0m                               Traceback (most recent call last)",
      "\u001b[0;31mSystemError\u001b[0m: PyEval_EvalFrameEx returned a result with an error set",
      "\nThe above exception was the direct cause of the following exception:\n",
      "\u001b[0;31mSystemError\u001b[0m                               Traceback (most recent call last)",
      "\u001b[0;31mSystemError\u001b[0m: PyEval_EvalFrameEx returned a result with an error set",
      "\nThe above exception was the direct cause of the following exception:\n",
      "\u001b[0;31mSystemError\u001b[0m                               Traceback (most recent call last)",
      "\u001b[0;31mSystemError\u001b[0m: PyEval_EvalFrameEx returned a result with an error set",
      "\nThe above exception was the direct cause of the following exception:\n",
      "\u001b[0;31mSystemError\u001b[0m                               Traceback (most recent call last)",
      "\u001b[0;31mSystemError\u001b[0m: PyEval_EvalFrameEx returned a result with an error set",
      "\nThe above exception was the direct cause of the following exception:\n",
      "\u001b[0;31mSystemError\u001b[0m                               Traceback (most recent call last)",
      "\u001b[0;31mSystemError\u001b[0m: PyEval_EvalFrameEx returned a result with an error set",
      "\nThe above exception was the direct cause of the following exception:\n",
      "\u001b[0;31mSystemError\u001b[0m                               Traceback (most recent call last)",
      "\u001b[0;31mSystemError\u001b[0m: PyEval_EvalFrameEx returned a result with an error set",
      "\nThe above exception was the direct cause of the following exception:\n",
      "\u001b[0;31mSystemError\u001b[0m                               Traceback (most recent call last)",
      "\u001b[0;31mSystemError\u001b[0m: PyEval_EvalFrameEx returned a result with an error set",
      "\nThe above exception was the direct cause of the following exception:\n",
      "\u001b[0;31mSystemError\u001b[0m                               Traceback (most recent call last)",
      "\u001b[0;31mSystemError\u001b[0m: PyEval_EvalFrameEx returned a result with an error set",
      "\nThe above exception was the direct cause of the following exception:\n",
      "\u001b[0;31mSystemError\u001b[0m                               Traceback (most recent call last)",
      "\u001b[0;31mSystemError\u001b[0m: PyEval_EvalFrameEx returned a result with an error set",
      "\nThe above exception was the direct cause of the following exception:\n",
      "\u001b[0;31mSystemError\u001b[0m                               Traceback (most recent call last)",
      "\u001b[0;31mSystemError\u001b[0m: PyEval_EvalFrameEx returned a result with an error set",
      "\nThe above exception was the direct cause of the following exception:\n",
      "\u001b[0;31mSystemError\u001b[0m                               Traceback (most recent call last)",
      "\u001b[0;31mSystemError\u001b[0m: PyEval_EvalFrameEx returned a result with an error set",
      "\nThe above exception was the direct cause of the following exception:\n",
      "\u001b[0;31mSystemError\u001b[0m                               Traceback (most recent call last)",
      "\u001b[0;31mSystemError\u001b[0m: PyEval_EvalFrameEx returned a result with an error set",
      "\nThe above exception was the direct cause of the following exception:\n",
      "\u001b[0;31mSystemError\u001b[0m                               Traceback (most recent call last)",
      "\u001b[0;31mSystemError\u001b[0m: PyEval_EvalFrameEx returned a result with an error set",
      "\nThe above exception was the direct cause of the following exception:\n",
      "\u001b[0;31mSystemError\u001b[0m                               Traceback (most recent call last)",
      "\u001b[0;31mSystemError\u001b[0m: PyEval_EvalFrameEx returned a result with an error set",
      "\nThe above exception was the direct cause of the following exception:\n",
      "\u001b[0;31mSystemError\u001b[0m                               Traceback (most recent call last)",
      "\u001b[0;31mSystemError\u001b[0m: PyEval_EvalFrameEx returned a result with an error set",
      "\nThe above exception was the direct cause of the following exception:\n",
      "\u001b[0;31mSystemError\u001b[0m                               Traceback (most recent call last)",
      "\u001b[0;31mSystemError\u001b[0m: PyEval_EvalFrameEx returned a result with an error set",
      "\nThe above exception was the direct cause of the following exception:\n",
      "\u001b[0;31mSystemError\u001b[0m                               Traceback (most recent call last)",
      "\u001b[0;31mSystemError\u001b[0m: PyEval_EvalFrameEx returned a result with an error set",
      "\nThe above exception was the direct cause of the following exception:\n",
      "\u001b[0;31mSystemError\u001b[0m                               Traceback (most recent call last)",
      "\u001b[0;31mSystemError\u001b[0m: PyEval_EvalFrameEx returned a result with an error set",
      "\nThe above exception was the direct cause of the following exception:\n",
      "\u001b[0;31mSystemError\u001b[0m                               Traceback (most recent call last)",
      "\u001b[0;31mSystemError\u001b[0m: PyEval_EvalFrameEx returned a result with an error set",
      "\nThe above exception was the direct cause of the following exception:\n",
      "\u001b[0;31mSystemError\u001b[0m                               Traceback (most recent call last)",
      "\u001b[0;31mSystemError\u001b[0m: PyEval_EvalFrameEx returned a result with an error set",
      "\nThe above exception was the direct cause of the following exception:\n",
      "\u001b[0;31mSystemError\u001b[0m                               Traceback (most recent call last)",
      "\u001b[0;31mSystemError\u001b[0m: PyEval_EvalFrameEx returned a result with an error set",
      "\nThe above exception was the direct cause of the following exception:\n",
      "\u001b[0;31mSystemError\u001b[0m                               Traceback (most recent call last)",
      "\u001b[0;31mSystemError\u001b[0m: PyEval_EvalFrameEx returned a result with an error set",
      "\nThe above exception was the direct cause of the following exception:\n",
      "\u001b[0;31mSystemError\u001b[0m                               Traceback (most recent call last)",
      "\u001b[0;31mSystemError\u001b[0m: PyEval_EvalFrameEx returned a result with an error set",
      "\nThe above exception was the direct cause of the following exception:\n",
      "\u001b[0;31mSystemError\u001b[0m                               Traceback (most recent call last)",
      "\u001b[0;31mSystemError\u001b[0m: PyEval_EvalFrameEx returned a result with an error set",
      "\nThe above exception was the direct cause of the following exception:\n",
      "\u001b[0;31mSystemError\u001b[0m                               Traceback (most recent call last)",
      "\u001b[0;31mSystemError\u001b[0m: PyEval_EvalFrameEx returned a result with an error set",
      "\nThe above exception was the direct cause of the following exception:\n",
      "\u001b[0;31mSystemError\u001b[0m                               Traceback (most recent call last)",
      "\u001b[0;31mSystemError\u001b[0m: PyEval_EvalFrameEx returned a result with an error set",
      "\nThe above exception was the direct cause of the following exception:\n",
      "\u001b[0;31mSystemError\u001b[0m                               Traceback (most recent call last)",
      "\u001b[0;31mSystemError\u001b[0m: PyEval_EvalFrameEx returned a result with an error set",
      "\nThe above exception was the direct cause of the following exception:\n",
      "\u001b[0;31mSystemError\u001b[0m                               Traceback (most recent call last)",
      "\u001b[0;31mSystemError\u001b[0m: PyEval_EvalFrameEx returned a result with an error set",
      "\nThe above exception was the direct cause of the following exception:\n",
      "\u001b[0;31mSystemError\u001b[0m                               Traceback (most recent call last)",
      "\u001b[0;31mSystemError\u001b[0m: PyEval_EvalFrameEx returned a result with an error set",
      "\nThe above exception was the direct cause of the following exception:\n",
      "\u001b[0;31mSystemError\u001b[0m                               Traceback (most recent call last)",
      "\u001b[0;31mSystemError\u001b[0m: PyEval_EvalFrameEx returned a result with an error set",
      "\nThe above exception was the direct cause of the following exception:\n",
      "\u001b[0;31mSystemError\u001b[0m                               Traceback (most recent call last)",
      "\u001b[0;31mSystemError\u001b[0m: PyEval_EvalFrameEx returned a result with an error set",
      "\nThe above exception was the direct cause of the following exception:\n",
      "\u001b[0;31mSystemError\u001b[0m                               Traceback (most recent call last)",
      "\u001b[0;31mSystemError\u001b[0m: PyEval_EvalFrameEx returned a result with an error set",
      "\nThe above exception was the direct cause of the following exception:\n",
      "\u001b[0;31mSystemError\u001b[0m                               Traceback (most recent call last)",
      "\u001b[0;31mSystemError\u001b[0m: PyEval_EvalFrameEx returned a result with an error set",
      "\nThe above exception was the direct cause of the following exception:\n",
      "\u001b[0;31mSystemError\u001b[0m                               Traceback (most recent call last)",
      "\u001b[0;31mSystemError\u001b[0m: PyEval_EvalFrameEx returned a result with an error set",
      "\nThe above exception was the direct cause of the following exception:\n",
      "\u001b[0;31mSystemError\u001b[0m                               Traceback (most recent call last)",
      "\u001b[0;31mSystemError\u001b[0m: PyEval_EvalFrameEx returned a result with an error set",
      "\nThe above exception was the direct cause of the following exception:\n",
      "\u001b[0;31mSystemError\u001b[0m                               Traceback (most recent call last)",
      "\u001b[0;31mSystemError\u001b[0m: PyEval_EvalFrameEx returned a result with an error set",
      "\nThe above exception was the direct cause of the following exception:\n",
      "\u001b[0;31mSystemError\u001b[0m                               Traceback (most recent call last)",
      "\u001b[0;31mSystemError\u001b[0m: PyEval_EvalFrameEx returned a result with an error set",
      "\nThe above exception was the direct cause of the following exception:\n",
      "\u001b[0;31mSystemError\u001b[0m                               Traceback (most recent call last)",
      "\u001b[0;31mSystemError\u001b[0m: PyEval_EvalFrameEx returned a result with an error set",
      "\nThe above exception was the direct cause of the following exception:\n",
      "\u001b[0;31mSystemError\u001b[0m                               Traceback (most recent call last)",
      "\u001b[0;31mSystemError\u001b[0m: PyEval_EvalFrameEx returned a result with an error set",
      "\nThe above exception was the direct cause of the following exception:\n",
      "\u001b[0;31mSystemError\u001b[0m                               Traceback (most recent call last)",
      "\u001b[0;31mSystemError\u001b[0m: PyEval_EvalFrameEx returned a result with an error set",
      "\nThe above exception was the direct cause of the following exception:\n",
      "\u001b[0;31mSystemError\u001b[0m                               Traceback (most recent call last)",
      "\u001b[0;31mSystemError\u001b[0m: PyEval_EvalFrameEx returned a result with an error set",
      "\nThe above exception was the direct cause of the following exception:\n",
      "\u001b[0;31mSystemError\u001b[0m                               Traceback (most recent call last)",
      "\u001b[0;31mSystemError\u001b[0m: PyEval_EvalFrameEx returned a result with an error set",
      "\nThe above exception was the direct cause of the following exception:\n",
      "\u001b[0;31mSystemError\u001b[0m                               Traceback (most recent call last)",
      "\u001b[0;31mSystemError\u001b[0m: PyEval_EvalFrameEx returned a result with an error set",
      "\nThe above exception was the direct cause of the following exception:\n",
      "\u001b[0;31mSystemError\u001b[0m                               Traceback (most recent call last)",
      "\u001b[0;31mSystemError\u001b[0m: PyEval_EvalFrameEx returned a result with an error set",
      "\nThe above exception was the direct cause of the following exception:\n",
      "\u001b[0;31mSystemError\u001b[0m                               Traceback (most recent call last)",
      "\u001b[0;31mSystemError\u001b[0m: PyEval_EvalFrameEx returned a result with an error set",
      "\nThe above exception was the direct cause of the following exception:\n",
      "\u001b[0;31mSystemError\u001b[0m                               Traceback (most recent call last)",
      "\u001b[0;31mSystemError\u001b[0m: PyEval_EvalFrameEx returned a result with an error set",
      "\nThe above exception was the direct cause of the following exception:\n",
      "\u001b[0;31mSystemError\u001b[0m                               Traceback (most recent call last)",
      "\u001b[0;31mSystemError\u001b[0m: PyEval_EvalFrameEx returned a result with an error set",
      "\nThe above exception was the direct cause of the following exception:\n",
      "\u001b[0;31mSystemError\u001b[0m                               Traceback (most recent call last)",
      "\u001b[0;31mSystemError\u001b[0m: PyEval_EvalFrameEx returned a result with an error set",
      "\nThe above exception was the direct cause of the following exception:\n",
      "\u001b[0;31mSystemError\u001b[0m                               Traceback (most recent call last)",
      "\u001b[0;31mSystemError\u001b[0m: PyEval_EvalFrameEx returned a result with an error set",
      "\nThe above exception was the direct cause of the following exception:\n",
      "\u001b[0;31mSystemError\u001b[0m                               Traceback (most recent call last)",
      "\u001b[0;31mSystemError\u001b[0m: PyEval_EvalFrameEx returned a result with an error set",
      "\nThe above exception was the direct cause of the following exception:\n",
      "\u001b[0;31mSystemError\u001b[0m                               Traceback (most recent call last)",
      "\u001b[0;31mSystemError\u001b[0m: PyEval_EvalFrameEx returned a result with an error set",
      "\nThe above exception was the direct cause of the following exception:\n",
      "\u001b[0;31mSystemError\u001b[0m                               Traceback (most recent call last)",
      "\u001b[0;31mSystemError\u001b[0m: PyEval_EvalFrameEx returned a result with an error set",
      "\nThe above exception was the direct cause of the following exception:\n",
      "\u001b[0;31mSystemError\u001b[0m                               Traceback (most recent call last)",
      "\u001b[0;31mSystemError\u001b[0m: PyEval_EvalFrameEx returned a result with an error set",
      "\nThe above exception was the direct cause of the following exception:\n",
      "\u001b[0;31mSystemError\u001b[0m                               Traceback (most recent call last)",
      "\u001b[0;31mSystemError\u001b[0m: PyEval_EvalFrameEx returned a result with an error set",
      "\nThe above exception was the direct cause of the following exception:\n",
      "\u001b[0;31mSystemError\u001b[0m                               Traceback (most recent call last)",
      "\u001b[0;31mSystemError\u001b[0m: PyEval_EvalFrameEx returned a result with an error set",
      "\nThe above exception was the direct cause of the following exception:\n",
      "\u001b[0;31mSystemError\u001b[0m                               Traceback (most recent call last)",
      "\u001b[0;31mSystemError\u001b[0m: PyEval_EvalFrameEx returned a result with an error set",
      "\nThe above exception was the direct cause of the following exception:\n",
      "\u001b[0;31mSystemError\u001b[0m                               Traceback (most recent call last)",
      "\u001b[0;31mSystemError\u001b[0m: PyEval_EvalFrameEx returned a result with an error set",
      "\nThe above exception was the direct cause of the following exception:\n",
      "\u001b[0;31mSystemError\u001b[0m                               Traceback (most recent call last)",
      "\u001b[0;31mSystemError\u001b[0m: PyEval_EvalFrameEx returned a result with an error set",
      "\nThe above exception was the direct cause of the following exception:\n",
      "\u001b[0;31mSystemError\u001b[0m                               Traceback (most recent call last)",
      "\u001b[0;31mSystemError\u001b[0m: PyEval_EvalFrameEx returned a result with an error set",
      "\nThe above exception was the direct cause of the following exception:\n",
      "\u001b[0;31mSystemError\u001b[0m                               Traceback (most recent call last)",
      "\u001b[0;31mSystemError\u001b[0m: PyEval_EvalFrameEx returned a result with an error set",
      "\nThe above exception was the direct cause of the following exception:\n",
      "\u001b[0;31mSystemError\u001b[0m                               Traceback (most recent call last)",
      "\u001b[0;31mSystemError\u001b[0m: PyEval_EvalFrameEx returned a result with an error set",
      "\nThe above exception was the direct cause of the following exception:\n",
      "\u001b[0;31mSystemError\u001b[0m                               Traceback (most recent call last)",
      "\u001b[0;31mSystemError\u001b[0m: PyEval_EvalFrameEx returned a result with an error set",
      "\nThe above exception was the direct cause of the following exception:\n",
      "\u001b[0;31mSystemError\u001b[0m                               Traceback (most recent call last)",
      "\u001b[0;31mSystemError\u001b[0m: PyEval_EvalFrameEx returned a result with an error set",
      "\nThe above exception was the direct cause of the following exception:\n",
      "\u001b[0;31mSystemError\u001b[0m                               Traceback (most recent call last)",
      "\u001b[0;31mSystemError\u001b[0m: PyEval_EvalFrameEx returned a result with an error set",
      "\nThe above exception was the direct cause of the following exception:\n",
      "\u001b[0;31mSystemError\u001b[0m                               Traceback (most recent call last)",
      "\u001b[0;31mSystemError\u001b[0m: PyEval_EvalFrameEx returned a result with an error set",
      "\nThe above exception was the direct cause of the following exception:\n",
      "\u001b[0;31mSystemError\u001b[0m                               Traceback (most recent call last)",
      "\u001b[0;31mSystemError\u001b[0m: PyEval_EvalFrameEx returned a result with an error set",
      "\nThe above exception was the direct cause of the following exception:\n",
      "\u001b[0;31mSystemError\u001b[0m                               Traceback (most recent call last)",
      "\u001b[0;31mSystemError\u001b[0m: PyEval_EvalFrameEx returned a result with an error set",
      "\nThe above exception was the direct cause of the following exception:\n",
      "\u001b[0;31mSystemError\u001b[0m                               Traceback (most recent call last)",
      "\u001b[0;31mSystemError\u001b[0m: PyEval_EvalFrameEx returned a result with an error set",
      "\nThe above exception was the direct cause of the following exception:\n",
      "\u001b[0;31mSystemError\u001b[0m                               Traceback (most recent call last)",
      "\u001b[0;31mSystemError\u001b[0m: PyEval_EvalFrameEx returned a result with an error set",
      "\nThe above exception was the direct cause of the following exception:\n",
      "\u001b[0;31mSystemError\u001b[0m                               Traceback (most recent call last)",
      "\u001b[0;31mSystemError\u001b[0m: PyEval_EvalFrameEx returned a result with an error set",
      "\nThe above exception was the direct cause of the following exception:\n",
      "\u001b[0;31mSystemError\u001b[0m                               Traceback (most recent call last)",
      "\u001b[0;31mSystemError\u001b[0m: PyEval_EvalFrameEx returned a result with an error set",
      "\nThe above exception was the direct cause of the following exception:\n",
      "\u001b[0;31mSystemError\u001b[0m                               Traceback (most recent call last)",
      "\u001b[0;31mSystemError\u001b[0m: PyEval_EvalFrameEx returned a result with an error set",
      "\nThe above exception was the direct cause of the following exception:\n",
      "\u001b[0;31mSystemError\u001b[0m                               Traceback (most recent call last)",
      "\u001b[0;31mSystemError\u001b[0m: PyEval_EvalFrameEx returned a result with an error set",
      "\nThe above exception was the direct cause of the following exception:\n",
      "\u001b[0;31mSystemError\u001b[0m                               Traceback (most recent call last)",
      "\u001b[0;31mSystemError\u001b[0m: PyEval_EvalFrameEx returned a result with an error set",
      "\nThe above exception was the direct cause of the following exception:\n",
      "\u001b[0;31mSystemError\u001b[0m                               Traceback (most recent call last)",
      "\u001b[0;31mSystemError\u001b[0m: PyEval_EvalFrameEx returned a result with an error set",
      "\nThe above exception was the direct cause of the following exception:\n",
      "\u001b[0;31mSystemError\u001b[0m                               Traceback (most recent call last)",
      "\u001b[0;31mSystemError\u001b[0m: PyEval_EvalFrameEx returned a result with an error set",
      "\nThe above exception was the direct cause of the following exception:\n",
      "\u001b[0;31mSystemError\u001b[0m                               Traceback (most recent call last)",
      "\u001b[0;31mSystemError\u001b[0m: PyEval_EvalFrameEx returned a result with an error set",
      "\nThe above exception was the direct cause of the following exception:\n",
      "\u001b[0;31mSystemError\u001b[0m                               Traceback (most recent call last)",
      "\u001b[0;31mSystemError\u001b[0m: PyEval_EvalFrameEx returned a result with an error set",
      "\nThe above exception was the direct cause of the following exception:\n",
      "\u001b[0;31mSystemError\u001b[0m                               Traceback (most recent call last)",
      "\u001b[0;31mSystemError\u001b[0m: PyEval_EvalFrameEx returned a result with an error set",
      "\nThe above exception was the direct cause of the following exception:\n",
      "\u001b[0;31mSystemError\u001b[0m                               Traceback (most recent call last)",
      "\u001b[0;31mSystemError\u001b[0m: PyEval_EvalFrameEx returned a result with an error set",
      "\nThe above exception was the direct cause of the following exception:\n",
      "\u001b[0;31mSystemError\u001b[0m                               Traceback (most recent call last)",
      "\u001b[0;31mSystemError\u001b[0m: PyEval_EvalFrameEx returned a result with an error set",
      "\nThe above exception was the direct cause of the following exception:\n",
      "\u001b[0;31mSystemError\u001b[0m                               Traceback (most recent call last)",
      "\u001b[0;31mSystemError\u001b[0m: PyEval_EvalFrameEx returned a result with an error set",
      "\nThe above exception was the direct cause of the following exception:\n",
      "\u001b[0;31mSystemError\u001b[0m                               Traceback (most recent call last)",
      "\u001b[0;31mSystemError\u001b[0m: PyEval_EvalFrameEx returned a result with an error set",
      "\nThe above exception was the direct cause of the following exception:\n",
      "\u001b[0;31mSystemError\u001b[0m                               Traceback (most recent call last)",
      "\u001b[0;31mSystemError\u001b[0m: PyEval_EvalFrameEx returned a result with an error set",
      "\nThe above exception was the direct cause of the following exception:\n",
      "\u001b[0;31mSystemError\u001b[0m                               Traceback (most recent call last)",
      "\u001b[0;31mSystemError\u001b[0m: PyEval_EvalFrameEx returned a result with an error set",
      "\nThe above exception was the direct cause of the following exception:\n",
      "\u001b[0;31mSystemError\u001b[0m                               Traceback (most recent call last)",
      "\u001b[0;31mSystemError\u001b[0m: PyEval_EvalFrameEx returned a result with an error set",
      "\nThe above exception was the direct cause of the following exception:\n",
      "\u001b[0;31mSystemError\u001b[0m                               Traceback (most recent call last)",
      "\u001b[0;31mSystemError\u001b[0m: PyEval_EvalFrameEx returned a result with an error set",
      "\nThe above exception was the direct cause of the following exception:\n",
      "\u001b[0;31mSystemError\u001b[0m                               Traceback (most recent call last)",
      "\u001b[0;31mSystemError\u001b[0m: PyEval_EvalFrameEx returned a result with an error set",
      "\nThe above exception was the direct cause of the following exception:\n",
      "\u001b[0;31mSystemError\u001b[0m                               Traceback (most recent call last)",
      "\u001b[0;31mSystemError\u001b[0m: PyEval_EvalFrameEx returned a result with an error set",
      "\nThe above exception was the direct cause of the following exception:\n",
      "\u001b[0;31mSystemError\u001b[0m                               Traceback (most recent call last)",
      "\u001b[0;31mSystemError\u001b[0m: PyEval_EvalFrameEx returned a result with an error set",
      "\nThe above exception was the direct cause of the following exception:\n",
      "\u001b[0;31mSystemError\u001b[0m                               Traceback (most recent call last)",
      "\u001b[0;31mSystemError\u001b[0m: PyEval_EvalFrameEx returned a result with an error set",
      "\nThe above exception was the direct cause of the following exception:\n",
      "\u001b[0;31mSystemError\u001b[0m                               Traceback (most recent call last)",
      "\u001b[0;31mSystemError\u001b[0m: PyEval_EvalFrameEx returned a result with an error set",
      "\nThe above exception was the direct cause of the following exception:\n",
      "\u001b[0;31mSystemError\u001b[0m                               Traceback (most recent call last)",
      "\u001b[0;31mSystemError\u001b[0m: PyEval_EvalFrameEx returned a result with an error set",
      "\nThe above exception was the direct cause of the following exception:\n",
      "\u001b[0;31mSystemError\u001b[0m                               Traceback (most recent call last)",
      "\u001b[0;31mSystemError\u001b[0m: PyEval_EvalFrameEx returned a result with an error set",
      "\nThe above exception was the direct cause of the following exception:\n",
      "\u001b[0;31mSystemError\u001b[0m                               Traceback (most recent call last)",
      "\u001b[0;31mSystemError\u001b[0m: PyEval_EvalFrameEx returned a result with an error set",
      "\nThe above exception was the direct cause of the following exception:\n",
      "\u001b[0;31mSystemError\u001b[0m                               Traceback (most recent call last)",
      "\u001b[0;31mSystemError\u001b[0m: PyEval_EvalFrameEx returned a result with an error set",
      "\nThe above exception was the direct cause of the following exception:\n",
      "\u001b[0;31mSystemError\u001b[0m                               Traceback (most recent call last)",
      "\u001b[0;31mSystemError\u001b[0m: PyEval_EvalFrameEx returned a result with an error set",
      "\nThe above exception was the direct cause of the following exception:\n",
      "\u001b[0;31mSystemError\u001b[0m                               Traceback (most recent call last)",
      "\u001b[0;31mSystemError\u001b[0m: PyEval_EvalFrameEx returned a result with an error set",
      "\nThe above exception was the direct cause of the following exception:\n",
      "\u001b[0;31mSystemError\u001b[0m                               Traceback (most recent call last)",
      "\u001b[0;31mSystemError\u001b[0m: PyEval_EvalFrameEx returned a result with an error set",
      "\nThe above exception was the direct cause of the following exception:\n",
      "\u001b[0;31mSystemError\u001b[0m                               Traceback (most recent call last)",
      "\u001b[0;31mSystemError\u001b[0m: PyEval_EvalFrameEx returned a result with an error set",
      "\nThe above exception was the direct cause of the following exception:\n",
      "\u001b[0;31mSystemError\u001b[0m                               Traceback (most recent call last)",
      "\u001b[0;31mSystemError\u001b[0m: PyEval_EvalFrameEx returned a result with an error set",
      "\nThe above exception was the direct cause of the following exception:\n",
      "\u001b[0;31mSystemError\u001b[0m                               Traceback (most recent call last)",
      "\u001b[0;31mSystemError\u001b[0m: PyEval_EvalFrameEx returned a result with an error set",
      "\nThe above exception was the direct cause of the following exception:\n",
      "\u001b[0;31mSystemError\u001b[0m                               Traceback (most recent call last)",
      "\u001b[0;31mSystemError\u001b[0m: PyEval_EvalFrameEx returned a result with an error set",
      "\nThe above exception was the direct cause of the following exception:\n",
      "\u001b[0;31mSystemError\u001b[0m                               Traceback (most recent call last)",
      "\u001b[0;31mSystemError\u001b[0m: PyEval_EvalFrameEx returned a result with an error set",
      "\nThe above exception was the direct cause of the following exception:\n",
      "\u001b[0;31mSystemError\u001b[0m                               Traceback (most recent call last)",
      "\u001b[0;31mSystemError\u001b[0m: PyEval_EvalFrameEx returned a result with an error set",
      "\nThe above exception was the direct cause of the following exception:\n",
      "\u001b[0;31mSystemError\u001b[0m                               Traceback (most recent call last)",
      "\u001b[0;31mSystemError\u001b[0m: PyEval_EvalFrameEx returned a result with an error set",
      "\nThe above exception was the direct cause of the following exception:\n",
      "\u001b[0;31mSystemError\u001b[0m                               Traceback (most recent call last)",
      "\u001b[0;31mSystemError\u001b[0m: PyEval_EvalFrameEx returned a result with an error set",
      "\nThe above exception was the direct cause of the following exception:\n",
      "\u001b[0;31mSystemError\u001b[0m                               Traceback (most recent call last)",
      "\u001b[0;31mSystemError\u001b[0m: PyEval_EvalFrameEx returned a result with an error set",
      "\nThe above exception was the direct cause of the following exception:\n",
      "\u001b[0;31mSystemError\u001b[0m                               Traceback (most recent call last)",
      "\u001b[0;31mSystemError\u001b[0m: PyEval_EvalFrameEx returned a result with an error set",
      "\nThe above exception was the direct cause of the following exception:\n",
      "\u001b[0;31mSystemError\u001b[0m                               Traceback (most recent call last)",
      "\u001b[0;31mSystemError\u001b[0m: PyEval_EvalFrameEx returned a result with an error set",
      "\nThe above exception was the direct cause of the following exception:\n",
      "\u001b[0;31mSystemError\u001b[0m                               Traceback (most recent call last)",
      "\u001b[0;31mSystemError\u001b[0m: PyEval_EvalFrameEx returned a result with an error set",
      "\nThe above exception was the direct cause of the following exception:\n",
      "\u001b[0;31mSystemError\u001b[0m                               Traceback (most recent call last)",
      "\u001b[0;31mSystemError\u001b[0m: PyEval_EvalFrameEx returned a result with an error set",
      "\nThe above exception was the direct cause of the following exception:\n",
      "\u001b[0;31mSystemError\u001b[0m                               Traceback (most recent call last)",
      "\u001b[0;31mSystemError\u001b[0m: PyEval_EvalFrameEx returned a result with an error set",
      "\nThe above exception was the direct cause of the following exception:\n",
      "\u001b[0;31mSystemError\u001b[0m                               Traceback (most recent call last)",
      "\u001b[0;31mSystemError\u001b[0m: PyEval_EvalFrameEx returned a result with an error set",
      "\nThe above exception was the direct cause of the following exception:\n",
      "\u001b[0;31mSystemError\u001b[0m                               Traceback (most recent call last)",
      "\u001b[0;32m<ipython-input-25-06d9299185c6>\u001b[0m in \u001b[0;36m<module>\u001b[0;34m\u001b[0m\n\u001b[0;32m----> 1\u001b[0;31m \u001b[0mm3t\u001b[0m\u001b[0;34m.\u001b[0m\u001b[0msequence_alignment\u001b[0m\u001b[0;34m(\u001b[0m\u001b[0;34m'aminoacids1:'\u001b[0m\u001b[0;34m+\u001b[0m\u001b[0msequence_system\u001b[0m\u001b[0;34m.\u001b[0m\u001b[0mreplace\u001b[0m\u001b[0;34m(\u001b[0m\u001b[0;34m'X'\u001b[0m\u001b[0;34m,\u001b[0m\u001b[0;34m'.'\u001b[0m\u001b[0;34m)\u001b[0m\u001b[0;34m,\u001b[0m\u001b[0;34m'aminoacids1:'\u001b[0m\u001b[0;34m+\u001b[0m\u001b[0mtarget_sequence\u001b[0m\u001b[0;34m.\u001b[0m\u001b[0mreplace\u001b[0m\u001b[0;34m(\u001b[0m\u001b[0;34m'X'\u001b[0m\u001b[0;34m,\u001b[0m\u001b[0;34m'.'\u001b[0m\u001b[0;34m)\u001b[0m\u001b[0;34m)\u001b[0m\u001b[0;34m[\u001b[0m\u001b[0;36m0\u001b[0m\u001b[0;34m]\u001b[0m\u001b[0;34m\u001b[0m\u001b[0;34m\u001b[0m\u001b[0m\n\u001b[0m",
      "\u001b[0;32m~/Trabajo/Proyectos/LabTools/MolModMT/molmodmt/sequence.py\u001b[0m in \u001b[0;36msequence_alignment\u001b[0;34m(ref_item, item, engine, prettyprint, prettyprint_alignment_index, **kwards)\u001b[0m\n\u001b[1;32m     19\u001b[0m         \u001b[0mgap_open\u001b[0m\u001b[0;34m=\u001b[0m\u001b[0;34m-\u001b[0m\u001b[0;36m10\u001b[0m\u001b[0;34m\u001b[0m\u001b[0;34m\u001b[0m\u001b[0m\n\u001b[1;32m     20\u001b[0m         \u001b[0mgap_extend\u001b[0m\u001b[0;34m=\u001b[0m\u001b[0;34m-\u001b[0m\u001b[0;36m0.5\u001b[0m\u001b[0;34m\u001b[0m\u001b[0;34m\u001b[0m\u001b[0m\n\u001b[0;32m---> 21\u001b[0;31m         \u001b[0malignment\u001b[0m \u001b[0;34m=\u001b[0m \u001b[0m_biopython_align\u001b[0m\u001b[0;34m.\u001b[0m\u001b[0mglobalds\u001b[0m\u001b[0;34m(\u001b[0m\u001b[0mtmp_ref_seq\u001b[0m\u001b[0;34m,\u001b[0m \u001b[0mtmp_seq\u001b[0m\u001b[0;34m,\u001b[0m \u001b[0mmatrix\u001b[0m\u001b[0;34m,\u001b[0m \u001b[0mgap_open\u001b[0m\u001b[0;34m,\u001b[0m \u001b[0mgap_extend\u001b[0m\u001b[0;34m)\u001b[0m\u001b[0;34m\u001b[0m\u001b[0;34m\u001b[0m\u001b[0m\n\u001b[0m\u001b[1;32m     22\u001b[0m         \u001b[0;32mdel\u001b[0m\u001b[0;34m(\u001b[0m\u001b[0m_biopython_MatrixInfo\u001b[0m\u001b[0;34m,\u001b[0m\u001b[0m_biopython_align\u001b[0m\u001b[0;34m,\u001b[0m\u001b[0mmatrix\u001b[0m\u001b[0;34m,\u001b[0m\u001b[0mgap_open\u001b[0m\u001b[0;34m,\u001b[0m\u001b[0mgap_extend\u001b[0m\u001b[0;34m,\u001b[0m\u001b[0mtmp_ref_seq\u001b[0m\u001b[0;34m,\u001b[0m\u001b[0mtmp_seq\u001b[0m\u001b[0;34m)\u001b[0m\u001b[0;34m\u001b[0m\u001b[0;34m\u001b[0m\u001b[0m\n\u001b[1;32m     23\u001b[0m \u001b[0;34m\u001b[0m\u001b[0m\n",
      "\u001b[0;32m~/Myopt/Miniconda/miniconda3/envs/UIBCDF_lab_dev/lib/python3.7/site-packages/Bio/pairwise2.py\u001b[0m in \u001b[0;36m__call__\u001b[0;34m(self, *args, **keywds)\u001b[0m\n\u001b[1;32m    406\u001b[0m             \u001b[0;34m\"\"\"Call the alignment instance already created.\"\"\"\u001b[0m\u001b[0;34m\u001b[0m\u001b[0;34m\u001b[0m\u001b[0m\n\u001b[1;32m    407\u001b[0m             \u001b[0mkeywds\u001b[0m \u001b[0;34m=\u001b[0m \u001b[0mself\u001b[0m\u001b[0;34m.\u001b[0m\u001b[0mdecode\u001b[0m\u001b[0;34m(\u001b[0m\u001b[0;34m*\u001b[0m\u001b[0margs\u001b[0m\u001b[0;34m,\u001b[0m \u001b[0;34m**\u001b[0m\u001b[0mkeywds\u001b[0m\u001b[0;34m)\u001b[0m\u001b[0;34m\u001b[0m\u001b[0;34m\u001b[0m\u001b[0m\n\u001b[0;32m--> 408\u001b[0;31m             \u001b[0;32mreturn\u001b[0m \u001b[0m_align\u001b[0m\u001b[0;34m(\u001b[0m\u001b[0;34m**\u001b[0m\u001b[0mkeywds\u001b[0m\u001b[0;34m)\u001b[0m\u001b[0;34m\u001b[0m\u001b[0;34m\u001b[0m\u001b[0m\n\u001b[0m\u001b[1;32m    409\u001b[0m \u001b[0;34m\u001b[0m\u001b[0m\n\u001b[1;32m    410\u001b[0m     \u001b[0;32mdef\u001b[0m \u001b[0m__getattr__\u001b[0m\u001b[0;34m(\u001b[0m\u001b[0mself\u001b[0m\u001b[0;34m,\u001b[0m \u001b[0mattr\u001b[0m\u001b[0;34m)\u001b[0m\u001b[0;34m:\u001b[0m\u001b[0;34m\u001b[0m\u001b[0;34m\u001b[0m\u001b[0m\n",
      "\u001b[0;32m~/Myopt/Miniconda/miniconda3/envs/UIBCDF_lab_dev/lib/python3.7/site-packages/Bio/pairwise2.py\u001b[0m in \u001b[0;36m_align\u001b[0;34m(sequenceA, sequenceB, match_fn, gap_A_fn, gap_B_fn, penalize_extend_when_opening, penalize_end_gaps, align_globally, gap_char, force_generic, score_only, one_alignment_only)\u001b[0m\n\u001b[1;32m    460\u001b[0m             \u001b[0msequenceA\u001b[0m\u001b[0;34m,\u001b[0m \u001b[0msequenceB\u001b[0m\u001b[0;34m,\u001b[0m \u001b[0mmatch_fn\u001b[0m\u001b[0;34m,\u001b[0m \u001b[0mopen_A\u001b[0m\u001b[0;34m,\u001b[0m \u001b[0mextend_A\u001b[0m\u001b[0;34m,\u001b[0m \u001b[0mopen_B\u001b[0m\u001b[0;34m,\u001b[0m\u001b[0;34m\u001b[0m\u001b[0;34m\u001b[0m\u001b[0m\n\u001b[1;32m    461\u001b[0m             \u001b[0mextend_B\u001b[0m\u001b[0;34m,\u001b[0m \u001b[0mpenalize_extend_when_opening\u001b[0m\u001b[0;34m,\u001b[0m \u001b[0mpenalize_end_gaps\u001b[0m\u001b[0;34m,\u001b[0m\u001b[0;34m\u001b[0m\u001b[0;34m\u001b[0m\u001b[0m\n\u001b[0;32m--> 462\u001b[0;31m             align_globally, score_only)\n\u001b[0m\u001b[1;32m    463\u001b[0m     \u001b[0;32melse\u001b[0m\u001b[0;34m:\u001b[0m\u001b[0;34m\u001b[0m\u001b[0;34m\u001b[0m\u001b[0m\n\u001b[1;32m    464\u001b[0m         matrices = _make_score_matrix_generic(\n",
      "\u001b[0;31mSystemError\u001b[0m: <built-in function _make_score_matrix_fast> returned a result with an error set"
     ]
    }
   ],
   "source": [
    "m3t.sequence_alignment('aminoacids1:'+sequence_system.replace('X','.'),'aminoacids1:'+target_sequence.replace('X','.'))[0]"
   ]
  },
  {
   "cell_type": "code",
   "execution_count": null,
   "metadata": {},
   "outputs": [],
   "source": [
    "system_EBNA1_DNA_loops = m3t.add_loop(system_EBNA1_DNA,target_sequence)"
   ]
  },
  {
   "cell_type": "code",
   "execution_count": null,
   "metadata": {},
   "outputs": [],
   "source": [
    "m3t.view(aa)"
   ]
  },
  {
   "cell_type": "code",
   "execution_count": 46,
   "metadata": {},
   "outputs": [],
   "source": [
    "from skbio import Protein\n",
    "from skbio.alignment import global_pairwise_align_protein"
   ]
  },
  {
   "cell_type": "code",
   "execution_count": 47,
   "metadata": {},
   "outputs": [],
   "source": [
    "s1 = Protein(sequence_system)\n",
    "s2 = Protein(target_sequence)"
   ]
  },
  {
   "cell_type": "code",
   "execution_count": 48,
   "metadata": {},
   "outputs": [
    {
     "name": "stderr",
     "output_type": "stream",
     "text": [
      "/home/diego/Myopt/Miniconda/miniconda3/envs/UIBCDF_lab_dev/lib/python3.7/site-packages/skbio/alignment/_pairwise.py:599: EfficiencyWarning: You're using skbio's python implementation of Needleman-Wunsch alignment. This is known to be very slow (e.g., thousands of times slower than a native C implementation). We'll be adding a faster version soon (see https://github.com/biocore/scikit-bio/issues/254 to track progress on this).\n",
      "  \"to track progress on this).\", EfficiencyWarning)\n"
     ]
    }
   ],
   "source": [
    "alignment, score, start_end_positions = global_pairwise_align_protein(s1, s2)"
   ]
  },
  {
   "cell_type": "code",
   "execution_count": 61,
   "metadata": {},
   "outputs": [
    {
     "data": {
      "text/plain": [
       "Protein\n",
       "---------------------------------------------------------------------\n",
       "Stats:\n",
       "    length: 334\n",
       "    has gaps: True\n",
       "    has degenerates: True\n",
       "    has definites: True\n",
       "    has stops: False\n",
       "---------------------------------------------------------------------\n",
       "0   --------XX XXXXXXXXXX XXXXXXXXXX XXKGGWFGKH RGQGGSNPKF ENIAEGLRAL\n",
       "60  LARSHVERTT DEGTWVAGVF VYGGSKTSLY NLRRGTALAI PQCRLTPLSR LPFGMAPGPG\n",
       "...\n",
       "240 KTSLYNLRRG TALAIPQCRL TPLSRLPFGM APGPGPQPGP LRESIVCYFM VFLQTHIFAE\n",
       "300 VLKDAIKDLV MTKPAPTCNI RVTVCSFDDG VDLP"
      ]
     },
     "execution_count": 61,
     "metadata": {},
     "output_type": "execute_result"
    }
   ],
   "source": []
  },
  {
   "cell_type": "code",
   "execution_count": null,
   "metadata": {},
   "outputs": [],
   "source": [
    ">>> from skbio import Protein\n",
    ">>> from skbio.alignment import local_pairwise_align_protein\n",
    ">>> s1 = Protein(\"HEAGAWGHEE\")\n",
    ">>> s2 = Protein(\"PAWHEAE\")\n",
    ">>> alignment, score, start_end_positions = local_pairwise_align_protein(\n",
    "...     s1, s2, 11, 1)"
   ]
  }
 ],
 "metadata": {
  "kernelspec": {
   "display_name": "Python 3",
   "language": "python",
   "name": "python3"
  },
  "language_info": {
   "codemirror_mode": {
    "name": "ipython",
    "version": 3
   },
   "file_extension": ".py",
   "mimetype": "text/x-python",
   "name": "python",
   "nbconvert_exporter": "python",
   "pygments_lexer": "ipython3",
   "version": "3.7.1"
  }
 },
 "nbformat": 4,
 "nbformat_minor": 2
}
